Workbook

Sheet Kundetilfredshetsundersøkelse -
A1: Response ID | B1: Date Created | C1: Date Modified | D1: IP Address | E1: Duration (sec) | F1: Response Status | G1: Email | H1: First Name | I1: Last Name | J1: Collector ID | K1: Collector Type | L1: Custom Value | M1: Velg selskap/kunde | N1: Tilbakemeldingen gjelder | O1: Tilbakemeldingen gjelder | P1: Tilbakemeldingen gjelder | Q1: Tilbakemeldingen gjelder | R1: Tilbakemeldingen gjelder | S1: Tilbakemeldingen gjelder | T1: Tilbakemeldingen gjelder | U1: Tilbakemeldingen gjelder | V1: Tilbakemeldingen gjelder | W1: Tilbakemeldingen gjelder | X1: Tilbakemeldingen gjelder | Y1: Tilbakemeldingen gjelder | Z1: Tilbakemeldingen gjelder | AA1: Tilbakemeldingen gjelder | AB1: Tilbakemeldingen gjelder | AC1: Tilbakemeldingen gjelder | AD1: Tilbakemeldingen gjelder | AE1: Tilbakemeldingen gjelder | AF1: Tilbakemeldingen gjelder | AG1: Hvor godt fornøyd er du med det utførte arbeidet til konsulenten fra JProfessionals AS | AH1: Hvor godt fornøyd er du med det utførte arbeidet til konsulenten fra JProfessionals AS | Kommentar | AI1: Har konsulenten fra JProfessionals AS den nødvendige kompetansen for arbeidet dere trenger utført? | AJ1: Har konsulenten fra JProfessionals AS den nødvendige kompetansen for arbeidet dere trenger utført? | Kommentar / Er det kompetanse du savner? | AK1: Hvor godt fornøyd er du med konsulenten fra JProfessionals AS sitt bidrag til kompetansedeling innad i ditt team/din organisasjon? | AL1: Hvor godt fornøyd er du med konsulenten fra JProfessionals AS sitt bidrag til kompetansedeling innad i ditt team/din organisasjon? | Kommentar | AM1: Hvor godt fornøyd er du med det generelle samarbeidet og kommunikasjonen med konsulenten fra JProfessionals AS? | AN1: Hvor godt fornøyd er du med det generelle samarbeidet og kommunikasjonen med konsulenten fra JProfessionals AS? | Kommentar | AO1: Hvor godt fornøyd er du med oppfølgingen fra, og samarbeidet med, JProfessionals AS? (valgfritt) - Om JProfessionals ikke er leverandøren du forholder deg til kan du se bort fra dette spørsmålet. | AP1: Hvor godt fornøyd er du med oppfølgingen fra, og samarbeidet med, JProfessionals AS? (valgfritt) - Om JProfessionals ikke er leverandøren du forholder deg til kan du se bort fra dette spørsmålet. | Kommentar | AQ1: I hvor stor grad synes du at kostnaden for konsulenten fra JProfessionals AS er verdt nytten de tilfører din organisasjon? | AR1: I hvor stor grad synes du at kostnaden for konsulenten fra JProfessionals AS er verdt nytten de tilfører din organisasjon? | Kommentar | AS1: Er det ytterligere områder eller tjenester du ser behov for bistand til?
A2: 114735374663 | B2: 45609.534 | C2: 45609.537 | D2: 62.92.224.122 | E2: 240 | F2: completed | G2: Not Answered | H2: Not Answered | I2: Not Answered | J2: 433598082 | K2: weblink | L2: Not Answered | M2: Husbanken | N2: Not Answered | O2: Not Answered | P2: Not Answered | Q2: Not Answered | R2: Not Answered | S2: Not Answered | T2: Not Answered | U2: Not Answered | V2: Not Answered | W2: Terje Wallem | X2: Not Answered | Y2: Not Answered | Z2: Not Answered | AA2: Not Answered | AB2: Not Answered | AC2: Not Answered | AD2: Not Answered | AE2: Not Answered | AF2: Not Answered | AG2: Svært fornøyd | AH2: Not Answered | AI2: I stor grad | AJ2: Not Answered | AK2: Svært fornøyd | AL2: Not Answered | AM2: Svært fornøyd | AN2: Not Answered | AO2: Svært fornøyd | AP2: (Overhuset) Ikke vært så mye dialog, men mangler ikke noe :-) | AQ2: 5 - star | AR2: Not Answered | AS2: Not Answered
A3: 114714414449 | B3: 45582.54 | C3: 45582.541 | D3: 81.175.27.28 | E3: 79 | F3: completed | G3: Not Answered | H3: Not Answered | I3: Not Answered | J3: 433188881 | K3: weblink | L3: Not Answered | M3: SPK | N3: Not Answered | O3: Not Answered | P3: Not Answered | Q3: Not Answered | R3: Not Answered | S3: Not Answered | T3: Not Answered | U3: Not Answered | V3: Not Answered | W3: Not Answered | X3: Not Answered | Y3: Not Answered | Z3: Not Answered | AA3: Not Answered | AB3: Not Answered | AC3: Not Answered | AD3: Not Answered | AE3: Not Answered | AF3: Ingebrigt Berg | AG3: Svært fornøyd | AH3: Kunnskapsrik, omgjengelig, tar initiativ. | AI3: I stor grad | AJ3: Not Answered | AK3: Svært fornøyd | AL3: Not Answered | AM3: Svært fornøyd | AN3: Not Answered | AO3: Not Answered | AP3: Not Answered | AQ3: I stor grad | AR3: Not Answered | AS3: Not Answered
A4: 114714413253 | B4: 45582.516 | C4: 45582.563 | D4: 46.212.44.252 | E4: 4100 | F4: completed | G4: Not Answered | H4: Not Answered | I4: Not Answered | J4: 433188881 | K4: weblink | L4: Not Answered | M4: Entur | N4: Not Answered | O4: Not Answered | P4: Not Answered | Q4: Not Answered | R4: Not Answered | S4: Not Answered | T4: Not Answered | U4: Not Answered | V4: Not Answered | W4: Not Answered | X4: Not Answered | Y4: Not Answered | Z4: Not Answered | AA4: Bent Lorentzen | AB4: Not Answered | AC4: Not Answered | AD4: Not Answered | AE4: Not Answered | AF4: Not Answered | AG4: Svært fornøyd | AH4: Bent er en svært kompetent teknolog som leverer arbeid av høy kvalitet. Hans erfaring og kompetanse innenfor feltet har bidratt til gode diskusjoner i teamet, gode løsninger, kunnskapsdeling og har vært med på å dra teamet i en veldig god retning. | AI4: I stor grad | AJ4: Bent har absolutt den nødvendige kompetansen for det arbeidet Entur trenger utført, og av de få områdene han ikke hadde kunnskap til fra før har han vist stor lærevilje og raskt kommet opp på et høyt kunnskapsnivå for ny teknologi og ikke minst domene. | AK4: Svært fornøyd | AL4: Som nevnt som kommentar i det første spørsmålet bidrar Bent i aller største grad til kompetansedeling innad i teamet. Hans evne til å vise forståelse og tålmodighet for de som skal tilegne seg ny kunnskap gjør han til en god mentor. | AM4: Svært fornøyd | AN4: Bent er veldig samarbeidsvillig og stiller alltid opp på kort varsel hvis noen trenger hjelp eller ønsker å arbeide sammen med ham. Bent og jeg (produktleder) har ukentlige møter for å planlegge uken jeg synes er veldig verdifullt. Han deltar alltid flittig i møter, har tydelige meninger, men er også alltid åpen for andres meninger og er villig til å diskutere emner med teamet før en endelig beslutning tas. | AO4: Not Answered | AP4: Not Answered | AQ4: I stor grad | AR4: Not Answered | AS4: Not Answered
A5: 114714432734 | B5: 45582.563 | C5: 45582.578 | D5: 46.212.44.252 | E5: 1236 | F5: completed | G5: Not Answered | H5: Not Answered | I5: Not Answered | J5: 433188881 | K5: weblink | L5: Not Answered | M5: Entur | N5: Not Answered | O5: Not Answered | P5: Not Answered | Q5: Not Answered | R5: Not Answered | S5: Not Answered | T5: Not Answered | U5: Not Answered | V5: Not Answered | W5: Not Answered | X5: Not Answered | Y5: Not Answered | Z5: Not Answered | AA5: Frederik Rønnevig | AB5: Not Answered | AC5: Not Answered | AD5: Not Answered | AE5: Not Answered | AF5: Not Answered | AG5: Svært fornøyd | AH5: Frederik har hovedansvaret for DevOps i teamet, og har bidratt til at teamet følger den ønskede infrastrukturen i Entur på en svært god måte i et helt nyoppstartet team (CI/CD-løp, GCP, tilgangsstyring mm). Han har også levert godt på selve applikasjonen vi utvikler på. | AI5: I stor grad | AJ5: Frederik har veldig god teknisk kompetanse både innenfor programmering og DevOps. Han er også svært lærevillig og setter alltid pris på å få nye oppgaver med teknologier han ikke har brukt før. | AK5: Svært fornøyd | AL5: Frederik er kanskje den på teamet som er aller best til å dokumentere både kode og prosesser i teamet, som legger til rette for at både teamet og eksterne enkelt kan sette seg inn i kode og prosesser og forstå hans tankeprosess ved valg. Han har også bidratt på dokumentasjonen til andre team for å gjøre det enklere for nestemann som skal lære seg det samme. | AM5: Svært fornøyd | AN5: Jeg er generelt svært fornøyd med både samarbeidet og kommunikasjonen til Frederik. Han stiller også alltid opp hvis noen trenger hjelp, løser gjerne oppgaver med andre og bidrar alltid til god stemning i teamet. Fordi jeg setter veldig pris på hans meninger skulle jeg kanskje ønske at han kunne vært enda litt mer på/med i diskusjoner i møter, men generelt er jeg svært fornøyd med samarbeidet vårt. | AO5: Not Answered | AP5: Not Answered | AQ5: I stor grad | AR5: Not Answered | AS5: Not Answered
A6: 114714444954 | B6: 45582.578 | C6: 45582.578 | D6: 46.212.44.252 | E6: 12 | F6: partial | G6: Not Answered | H6: Not Answered | I6: Not Answered | J6: 433188881 | K6: weblink | L6: Not Answered | M6: Entur | N6: Not Answered | O6: Not Answered | P6: Not Answered | Q6: Not Answered | R6: Not Answered | S6: Not Answered | T6: Not Answered | U6: Not Answered | V6: Not Answered | W6: Not Answered | X6: Not Answered | Y6: Not Answered | Z6: Not Answered | AA6: Frederik Rønnevig | AB6: Not Answered | AC6: Not Answered | AD6: Not Answered | AE6: Not Answered | AF6: Not Answered | AG6: Not Answered | AH6: Not Answered | AI6: Not Answered | AJ6: Not Answered | AK6: Not Answered | AL6: Not Answered | AM6: Not Answered | AN6: Not Answered | AO6: Not Answered | AP6: Not Answered | AQ6: Not Answered | AR6: Not Answered | AS6: Not Answered
A7: 114714509378 | B7: 45582.637 | C7: 45582.649 | D7: 188.95.247.201 | E7: 978 | F7: completed | G7: Not Answered | H7: Not Answered | I7: Not Answered | J7: 433188881 | K7: weblink | L7: Not Answered | M7: Ruter/TET Digital | N7: Not Answered | O7: Not Answered | P7: Not Answered | Q7: Not Answered | R7: David Børresen | S7: Not Answered | T7: Not Answered | U7: Not Answered | V7: Not Answered | W7: Not Answered | X7: Not Answered | Y7: Not Answered | Z7: Not Answered | AA7: Not Answered | AB7: Not Answered | AC7: Not Answered | AD7: Not Answered | AE7: Not Answered | AF7: Not Answered | AG7: Svært fornøyd | AH7: Ekstremt kunnig inom sitt fag. Leverarar alltid. Har gjort ett arbete jag har svårt att se att någon andra kan göra lika bra. | AI7: I stor grad | AJ7: Otveksamt | AK7: Litt fornøyd | AL7: Båda konsulenterna sitter på så bra kompetans som är högre än andra i sällskapet. Jag skulle gärna se att dom delar med sig mer av det. Kan se att det kan vara aktuellt att dom delar med sig av sitt arbete i mycket större utsträckning på Ruter/TET. Kan vara mer aktuellt när vi har mer på plats att visa mer emot ledelsen ect | AM7: Svært fornøyd | AN7: Superenkelt att jobba med, enkel transparant kommunikation. Vågar komma med bra feedback ifall han inte är enig i saker. Alltid trevligt att prata med. | AO7: Litt fornøyd | AP7: Osäker på denna, Känner egentligen att jag inte har ett direkt förhållande emot JPro | AQ7: 5 - star | AR7: Smakar det så kostar det är väll det dom säger. | AS7: Inte för tillfället ifrån Jpro
A8: 114714523977 | B8: 45582.649 | C8: 45582.653 | D8: 188.95.247.201 | E8: 360 | F8: completed | G8: Not Answered | H8: Not Answered | I8: Not Answered | J8: 433188881 | K8: weblink | L8: Not Answered | M8: Ruter/TET Digital | N8: Not Answered | O8: Not Answered | P8: Not Answered | Q8: Not Answered | R8: Ole Kristian Fjærestad | S8: Not Answered | T8: Not Answered | U8: Not Answered | V8: Not Answered | W8: Not Answered | X8: Not Answered | Y8: Not Answered | Z8: Not Answered | AA8: Not Answered | AB8: Not Answered | AC8: Not Answered | AD8: Not Answered | AE8: Not Answered | AF8: Not Answered | AG8: Svært fornøyd | AH8: För mig känns det som Ole Kristian inte bara tar design som facit, utan höjer arbetet och tänker ett steg längre. För mig är det ett signalement för en väldigt duktig utvecklare. Allt som jag sätt Ole kristian levererar är i hög klass. | AI8: I stor grad | AJ8: Absolut. | AK8: Litt fornøyd | AL8: Se min tidigare kommentar. Jag skulle gärna se (kanske i en framtid när mer är på plats) att Ole kristian delar med sig mer av sitt arbete bredare inom organisationen. Tror mycket av arbetet är väldigt uppskattat av utvecklare, men jag vill gärna att andra fag ser nyttan och kvaliteten. | AM8: Svært fornøyd | AN8: Ole kristian är superenkel att jobba med, Kommer med bra inspel och tankar. Alltid ett nöje att prata med och jag ser fram emot att sitta sammen med på kontoret. | AO8: Litt fornøyd | AP8: Se tidigare kommentar om detta, har som sagt inget direkt förhållande till Jpro | AQ8: 5 - star | AR8: Smakar det så kostar det. | AS8: Nej, inte nu
A9: 114716500340 | B9: 45585.557 | C9: 45585.558 | D9: 46.212.188.97 | E9: 123 | F9: completed | G9: Not Answered | H9: Not Answered | I9: Not Answered | J9: 433188881 | K9: weblink | L9: Not Answered | M9: NRK | N9: Not Answered | O9: Not Answered | P9: Not Answered | Q9: Not Answered | R9: Not Answered | S9: Not Answered | T9: Not Answered | U9: Audun Småge | V9: Not Answered | W9: Not Answered | X9: Not Answered | Y9: Not Answered | Z9: Not Answered | AA9: Not Answered | AB9: Not Answered | AC9: Not Answered | AD9: Not Answered | AE9: Not Answered | AF9: Not Answered | AG9: Svært fornøyd | AH9: Not Answered | AI9: I stor grad | AJ9: han er den på teamet med best kompetanse | AK9: Svært fornøyd | AL9: kjempefornøyd og håper å kunne få jobbe med ham veldig mye lengre! | AM9: Svært fornøyd | AN9: har likt alle konsulentene jeg har jobbet med og møtt fra JPro | AO9: Svært fornøyd | AP9: har ikke hatt veldig mye med dem direkte selv, bortsatt fra via Audun | AQ9: I stor grad | AR9: akkurat nå er han den jeg trenger mest på teamet, og det er verd prisen | AS9: Not Answered
A10: 114718049141 | B10: 45587.639 | C10: 45587.639 | D10: 195.18.187.143 | E10: 14 | F10: partial | G10: Not Answered | H10: Not Answered | I10: Not Answered | J10: 433188881 | K10: weblink | L10: Not Answered | M10: Statnett | N10: Not Answered | O10: Frode Roxrud Gill | P10: Not Answered | Q10: Not Answered | R10: Not Answered | S10: Not Answered | T10: Not Answered | U10: Not Answered | V10: Not Answered | W10: Not Answered | X10: Not Answered | Y10: Not Answered | Z10: Not Answered | AA10: Not Answered | AB10: Not Answered | AC10: Not Answered | AD10: Not Answered | AE10: Not Answered | AF10: Not Answered | AG10: Not Answered | AH10: Not Answered | AI10: Not Answered | AJ10: Not Answered | AK10: Not Answered | AL10: Not Answered | AM10: Not Answered | AN10: Not Answered | AO10: Not Answered | AP10: Not Answered | AQ10: Not Answered | AR10: Not Answered | AS10: Not Answered
A11: 114718079755 | B11: 45587.662 | C11: 45587.662 | D11: 195.18.187.144 | E11: 7 | F11: partial | G11: Not Answered | H11: Not Answered | I11: Not Answered | J11: 433188881 | K11: weblink | L11: Not Answered | M11: Statnett | N11: Not Answered | O11: Not Answered | P11: Not Answered | Q11: Not Answered | R11: Not Answered | S11: Not Answered | T11: Not Answered | U11: Not Answered | V11: Not Answered | W11: Not Answered | X11: Not Answered | Y11: Not Answered | Z11: Not Answered | AA11: Not Answered | AB11: Not Answered | AC11: Not Answered | AD11: Not Answered | AE11: Not Answered | AF11: Not Answered | AG11: Not Answered | AH11: Not Answered | AI11: Not Answered | AJ11: Not Answered | AK11: Not Answered | AL11: Not Answered | AM11: Not Answered | AN11: Not Answered | AO11: Not Answered | AP11: Not Answered | AQ11: Not Answered | AR11: Not Answered | AS11: Not Answered
A12: 114718956197 | B12: 45588.566 | C12: 45588.571 | D12: 81.166.197.7 | E12: 453 | F12: completed | G12: Not Answered | H12: Not Answered | I12: Not Answered | J12: 433188881 | K12: weblink | L12: Not Answered | M12: Aker Solutions | N12: Not Answered | O12: Not Answered | P12: Not Answered | Q12: Not Answered | R12: Not Answered | S12: Not Answered | T12: Not Answered | U12: Not Answered | V12: Not Answered | W12: Not Answered | X12: Not Answered | Y12: Michael Karén | Z12: Not Answered | AA12: Not Answered | AB12: Not Answered | AC12: Not Answered | AD12: Not Answered | AE12: Not Answered | AF12: Not Answered | AG12: Svært fornøyd | AH12: Veldig godt fornøyd med Michael's innsats. Han tar ansvar og bidrar aktivt med gode innspill, i motsetning til å 'bare gjøre som han får beskjed om'. | AI12: I stor grad | AJ12: Savner ingenting | AK12: Svært fornøyd | AL12: Vanskelig å kommentere direkte da jeg ikke er utvikler selv, men mitt inntrykk er at FE teamet jobber godt sammen | AM12: Svært fornøyd | AN12: Fungerer veldig bra. | AO12: Not Answered | AP12: Not Answered | AQ12: 5 - star | AR12: Har ikke innsyn i kostnader | AS12: Ingenting konkret.
A13: 114719061196 | B13: 45588.658 | C13: 45588.664 | D13: 195.18.187.143 | E13: 580 | F13: completed | G13: Not Answered | H13: Not Answered | I13: Not Answered | J13: 433188881 | K13: weblink | L13: Not Answered | M13: Statnett | N13: Not Answered | O13: Frode Roxrud Gill | P13: Not Answered | Q13: Not Answered | R13: Not Answered | S13: Not Answered | T13: Not Answered | U13: Not Answered | V13: Not Answered | W13: Not Answered | X13: Not Answered | Y13: Not Answered | Z13: Not Answered | AA13: Not Answered | AB13: Not Answered | AC13: Not Answered | AD13: Not Answered | AE13: Not Answered | AF13: Not Answered | AG13: Ganske fornøyd | AH13: Not Answered | AI13: 4 - star | AJ13: Måtte friske opp litt, lære seg noe nytt - men dette har gått bra og vi er fornøyde i dag. | AK13: Litt fornøyd | AL13: Har ikke hatt mulighet til å gjøre dette foreløpig, men kommer nå inn i e større team og vil kunne vise seg frem. Burde hatt en mulighet til å svare ikke aktuelt ;) | AM13: Svært fornøyd | AN13: Not Answered | AO13: Ganske fornøyd | AP13: Fornøyd med erstatning og prosessen rundt dette (var smidig). | AQ13: 4 - star | AR13: Vi leide inn en med litt annen kompetanse og konsulenten som nå bekler oppdraget har smalere kompetanse. Derfor er ikke forholdet mellom pris og leveranse like godt som det var opprinnelig. | AS13: Not Answered
... A40: 114756477385 | B40: 45637.398 | C40: 45637.399 | D40: 151.187.161.6 | E40: 72 | F40: completed | G40: Not Answered | H40: Not Answered | I40: Not Answered | J40: 433188881 | K40: weblink | L40: Not Answered | M40: Skatteetaten | N40: Rune Offerdal | O40: Not Answered | P40: Not Answered | Q40: Not Answered | R40: Not Answered | S40: Not Answered | T40: Not Answered | U40: Not Answered | V40: Not Answered | W40: Not Answered | X40: Not Answered | Y40: Not Answered | Z40: Not Answered | AA40: Not Answered | AB40: Not Answered | AC40: Not Answered | AD40: Not Answered | AE40: Not Answered | AF40: Not Answered | AG40: Svært fornøyd | AH40: Not Answered | AI40: I stor grad | AJ40: Not Answered | AK40: Svært fornøyd | AL40: Not Answered | AM40: Svært fornøyd | AN40: Not Answered | AO40: Not Answered | AP40: Not Answered | AQ40: 5 - star | AR40: Not Answered | AS40: Not Answered

Sheet Sheet6
A1: Response ID | B1: Date Created | C1: Date Modified | D1: IP Address | E1: Duration (sec) | F1: Response Status | G1: Email | H1: First Name | I1: Last Name | J1: Collector ID | K1: Collector Type | L1: Custom Value | M1: Konsulent | N1: Velg selskap/kunde | O1: Tilbakemeldingen gjelder | P1: Tilbakemeldingen gjelder | Q1: Tilbakemeldingen gjelder | R1: Tilbakemeldingen gjelder | S1: Tilbakemeldingen gjelder | T1: Tilbakemeldingen gjelder | U1: Tilbakemeldingen gjelder | V1: Tilbakemeldingen gjelder | W1: Tilbakemeldingen gjelder | X1: Tilbakemeldingen gjelder | Y1: Tilbakemeldingen gjelder | Z1: Tilbakemeldingen gjelder | AA1: Hvor godt fornøyd er du med det utførte arbeidet til konsulenten fra JProfessionals AS | AB1: Hvor godt fornøyd er du med det utførte arbeidet til konsulenten fra JProfessionals AS | Kommentar | AC1: Har konsulenten fra JProfessionals AS den nødvendige kompetansen for arbeidet dere trenger utført? | AD1: Har konsulenten fra JProfessionals AS den nødvendige kompetansen for arbeidet dere trenger utført? | Kommentar / Er det kompetanse du savner? | AE1: Hvor godt fornøyd er du med konsulenten fra JProfessionals AS sitt bidrag til kompetansedeling innad i ditt team/din organisasjon? | AF1: Hvor godt fornøyd er du med konsulenten fra JProfessionals AS sitt bidrag til kompetansedeling innad i ditt team/din organisasjon? | Kommentar | AG1: Hvor godt fornøyd er du med det generelle samarbeidet og kommunikasjonen med konsulenten fra JProfessionals AS? | AH1: Hvor godt fornøyd er du med det generelle samarbeidet og kommunikasjonen med konsulenten fra JProfessionals AS? | Kommentar | AI1: Hvor godt fornøyd er du med oppfølgingen fra, og samarbeidet med, JProfessionals AS? (valgfritt) - Om JProfessionals ikke er leverandøren du forholder deg til kan du se bort fra dette spørsmålet. | AJ1: Hvor godt fornøyd er du med oppfølgingen fra, og samarbeidet med, JProfessionals AS? (valgfritt) - Om JProfessionals ikke er leverandøren du forholder deg til kan du se bort fra dette spørsmålet. | Kommentar | AK1: I hvor stor grad synes du at kostnaden for konsulenten fra JProfessionals AS er verdt nytten de tilfører din organisasjon? | AL1: I hvor stor grad synes du at kostnaden for konsulenten fra JProfessionals AS er verdt nytten de tilfører din organisasjon? | Kommentar | AM1: Er det ytterligere områder eller tjenester du ser behov for bistand til?
A2: 114435056470 | B2: 45211.553 | C2: 45211.553 | D2: 78.82.46.215 | E2: 10 | F2: partial | G2: Not Answered | H2: Not Answered | I2: Not Answered | J2: 427821263 | K2: weblink | L2: Not Answered | M2: Not Answered | N2: Tolletaten | O2: Not Answered | P2: Not Answered | Q2: Not Answered | R2: Not Answered | S2: Not Answered | T2: Not Answered | U2: Not Answered | V2: Not Answered | W2: Not Answered | X2: Not Answered | Y2: Not Answered | Z2: Not Answered | AA2: Not Answered | AB2: Not Answered | AC2: Not Answered | AD2: Not Answered | AE2: Not Answered | AF2: Not Answered | AG2: Not Answered | AH2: Not Answered | AI2: Not Answered | AJ2: Not Answered | AK2: Not Answered | AL2: Not Answered | AM2: Not Answered
A3: 114452562205 | B3: 45232.449 | C3: 45232.451 | D3: 80.203.100.46 | E3: 127 | F3: completed | G3: Not Answered | H3: Not Answered | I3: Not Answered | J3: 427821263 | K3: weblink | L3: Not Answered | M3: Not Answered | N3: NAV | O3: Not Answered | P3: Not Answered | Q3: Not Answered | R3: Not Answered | S3: Not Answered | T3: Not Answered | U3: Not Answered | V3: Not Answered | W3: Not Answered | X3: Not Answered | Y3: Not Answered | Z3: Håvard Andersen | AA3: Svært fornøyd | AB3: Not Answered | AC3: I stor grad | AD3: Not Answered | AE3: Svært fornøyd | AF3: Not Answered | AG3: Svært fornøyd | AH3: Not Answered | AI3: Not Answered | AJ3: Not Answered | AK3: 5 - star | AL3: Not Answered | AM3: Not Answered
A4: 114452629995 | B4: 45232.521 | C4: 45232.528 | D4: 155.55.51.185 | E4: 631 | F4: completed | G4: Not Answered | H4: Not Answered | I4: Not Answered | J4: 427821263 | K4: weblink | L4: Not Answered | M4: Not Answered | N4: NAV | O4: Not Answered | P4: Not Answered | Q4: Not Answered | R4: Not Answered | S4: Not Answered | T4: Not Answered | U4: Not Answered | V4: Not Answered | W4: Not Answered | X4: Not Answered | Y4: Not Answered | Z4: Ingleiv Johansen | AA4: Svært fornøyd | AB4: Not Answered | AC4: I stor grad | AD4: Not Answered | AE4: Svært fornøyd | AF4: Opplever Ingleiv som en person som er flink til å dele generelt og opptatt av å formidle sin kompetanse på en måte som resten av teamet forstår | AG4: Svært fornøyd | AH4: Ingleiv er en veldig positiv og løsningsorientert person som er lett å samarbeide med. | AI4: Not Answered | AJ4: Not Answered | AK4: 5 - star | AL4: Opplever at Ingleiv er vel verdt kostnaden. | AM4: Not Answered
A5: 114455711454 | B5: 45236.327 | C5: 45236.34 | D5: 155.55.51.185 | E5: 1075 | F5: completed | G5: Not Answered | H5: Not Answered | I5: Not Answered | J5: 427821263 | K5: weblink | L5: Not Answered | M5: Not Answered | N5: NAV | O5: Not Answered | P5: Not Answered | Q5: Not Answered | R5: Not Answered | S5: Not Answered | T5: Not Answered | U5: Not Answered | V5: Not Answered | W5: Not Answered | X5: Not Answered | Y5: Not Answered | Z5: Espen Schei | AA5: Svært fornøyd | AB5: Espen utfører arbeidet på en svært god måte. Han er fremoverlent, løsningsorientert, proaktiv og ikke minst, leverer svært høy kvalitet. Han er en viktig driver i teamet og en viktig nøkkelperson for mange av våre problemstillinger. | AC5: I stor grad | AD5: Jeg opplever at han har kompetansen vi trenger for at han skal utføre oppdraget, og de riktige egenskapene til å sette seg inn i bredden og kompleksiteten i faget vi har som oppdrag å levere på. | AE5: Svært fornøyd | AF5: Jeg opplever at Espen deler, diskuter og reflekterer godt over valgt om løsninger og deler det aktivt med teamet. | AG5: Svært fornøyd | AH5: Jeg opplever at vi har en god og åpen dialog, og at samarbeidet fungerer godt. Espen er enkel å prate med og gjør seg noen gode betrakninger når vi diskuterer arbeidet. | AI5: Not Answered | AJ5: Not Answered | AK5: I stor grad | AL5: Espen er en av våre viktigste pådrivere og har bidratt utrolig mye for at vi skal komme i mål med oppdraget (reform) vårt innen deadline. | AM5: Not Answered
A6: 114457987830 | B6: 45238.426 | C6: 45238.441 | D6: 84.214.218.29 | E6: 1270 | F6: completed | G6: Not Answered | H6: Not Answered | I6: Not Answered | J6: 427821263 | K6: weblink | L6: Not Answered | M6: Not Answered | N6: NAV | O6: Not Answered | P6: Not Answered | Q6: Not Answered | R6: Not Answered | S6: Not Answered | T6: Not Answered | U6: Not Answered | V6: Not Answered | W6: Not Answered | X6: Not Answered | Y6: Not Answered | Z6: Anton Fofanov | AA6: Svært fornøyd | AB6: Not Answered | AC6: I stor grad | AD6: Anton har god kompetanse og leverer godt på alle områder. Hvis han får en vanskelig problemstilling så er han god på å tilegne seg kompetanse på teknologien og domenet og får arbeidet godt utført. | AE6: Ganske fornøyd | AF6: Anton er god på å diskutere samt dele kompetanse i sitt team og i organisasjonen. | AG6: Svært fornøyd | AH6: Not Answered | AI6: Not Answered | AJ6: Not Answered | AK6: 5 - star | AL6: Konsulenter er dyrt, men Anton har levert godt på alle arbeidsoppgaver han har fått. | AM6: Not Answered
A7: 114432085003 | B7: 45208.513 | C7: 45208.514 | D7: 195.18.187.144 | E7: 122 | F7: completed | G7: Not Answered | H7: Not Answered | I7: Not Answered | J7: 427944757 | K7: weblink | L7: Not Answered | M7: Not Answered | N7: Statnett | O7: Not Answered | P7: Dejan Maric | Q7: Not Answered | R7: Not Answered | S7: Not Answered | T7: Not Answered | U7: Not Answered | V7: Not Answered | W7: Not Answered | X7: Not Answered | Y7: Not Answered | Z7: Not Answered | AA7: Svært fornøyd | AB7: Not Answered | AC7: I stor grad | AD7: Not Answered | AE7: Svært fornøyd | AF7: Not Answered | AG7: Svært fornøyd | AH7: Not Answered | AI7: Not Answered | AJ7: Not Answered | AK7: 5 - star | AL7: Not Answered | AM7: Not Answered
A8: 114432951788 | B8: 45209.455 | C8: 45209.457 | D8: 160.67.51.32 | E8: 221 | F8: completed | G8: Not Answered | H8: Not Answered | I8: Not Answered | J8: 427944757 | K8: weblink | L8: Not Answered | M8: Not Answered | N8: NRK | O8: Not Answered | P8: Not Answered | Q8: Not Answered | R8: Not Answered | S8: Not Answered | T8: Not Answered | U8: Not Answered | V8: Audun Småge | W8: Not Answered | X8: Not Answered | Y8: Not Answered | Z8: Not Answered | AA8: Svært fornøyd | AB8: hyggelig å jobbe med, flink i de han gjør, viser at han bryr seg om å lage best mulig løsning for NRK. Ressurs og støttespiller inn i teamet som nå har en rekke nye ansatte. Hyggelig, rolig og omgjengelig. | AC8: I stor grad | AD8: han har absolutt riktig kompetanse for dette teamet, og vil bli savnet når han forsvinner til andre kunder | AE8: Svært fornøyd | AF8: deler kompetanse både i møter, i diskusjoner, gjennom codereview og eller der det er naturlig. Lett å spørre om hjelp. | AG8: Svært fornøyd | AH8: velig fornøyd! | AI8: Not Answered | AJ8: Not Answered | AK8: I stor grad | AL8: Not Answered | AM8: Not Answered
A9: 114433028131 | B9: 45209.553 | C9: 45209.556 | D9: 160.67.1.133 | E9: 213 | F9: completed | G9: Not Answered | H9: Not Answered | I9: Not Answered | J9: 427944757 | K9: weblink | L9: Not Answered | M9: Not Answered | N9: NRK | O9: Not Answered | P9: Not Answered | Q9: Not Answered | R9: Not Answered | S9: Not Answered | T9: Not Answered | U9: Not Answered | V9: Christian Wiik | W9: Not Answered | X9: Not Answered | Y9: Not Answered | Z9: Not Answered | AA9: Svært fornøyd | AB9: veldig fornøyd med utført arbeid og med konsulenten. Han tar ansvar, er en viktig spiller i teamet, sier fra dersom det er noe som kan forbedres, kjenner god til løsningen og er en meget viktig person for teamet og NRK | AC9: I stor grad | AD9: Absolutt nødvendig kompetanse og er en ressurs i teamet - spesielt nå når vi har flere nye i teamet | AE9: Svært fornøyd | AF9: god på å dele kompetanse, enten en-til-en, i parprogrammering, eller i større fora. Skal nå også dele større ting vi har gjort i teamet med hele teknologidivisjonen i NRK. | AG9: Svært fornøyd | AH9: Meget fornøyd med det generelle arbeidet og alt i alt innstillingen til Christian. Han blir savnet når han en dag går videre til neste oppdrag. | AI9: Not Answered | AJ9: Not Answered | AK9: I stor grad | AL9: Not Answered | AM9: Not Answered
A10: 114433974193 | B10: 45210.446 | C10: 45210.447 | D10: 78.41.46.2 | E10: 58 | F10: completed | G10: Not Answered | H10: Not Answered | I10: Not Answered | J10: 427944757 | K10: weblink | L10: Not Answered | M10: Not Answered | N10: Digitaliseringsdirektoratet | O10: Not Answered | P10: Not Answered | Q10: Not Answered | R10: Not Answered | S10: Not Answered | T10: Not Answered | U10: Not Answered | V10: Not Answered | W10: Not Answered | X10: Not Answered | Y10: Anne Marte Hjemås | Z10: Not Answered | AA10: Svært fornøyd | AB10: Not Answered | AC10: I stor grad | AD10: Not Answered | AE10: Ganske fornøyd | AF10: Not Answered | AG10: Svært fornøyd | AH10: Not Answered | AI10: Litt fornøyd | AJ10: Not Answered | AK10: 4 - star | AL10: Not Answered | AM10: Not Answered
A11: 114433974925 | B11: 45210.447 | C11: 45210.448 | D11: 78.41.46.2 | E11: 44 | F11: completed | G11: Not Answered | H11: Not Answered | I11: Not Answered | J11: 427944757 | K11: weblink | L11: Not Answered | M11: Not Answered | N11: Digitaliseringsdirektoratet | O11: Not Answered | P11: Not Answered | Q11: Not Answered | R11: Not Answered | S11: Not Answered | T11: Not Answered | U11: Not Answered | V11: Not Answered | W11: Not Answered | X11: Not Answered | Y11: Frode Bjerkholt | Z11: Not Answered | AA11: Svært fornøyd | AB11: Not Answered | AC11: I stor grad | AD11: Not Answered | AE11: Ganske fornøyd | AF11: Not Answered | AG11: Ganske fornøyd | AH11: Not Answered | AI11: Litt fornøyd | AJ11: Not Answered | AK11: 4 - star | AL11: Not Answered | AM11: Not Answered
A12: 114433975481 | B12: 45210.448 | C12: 45210.448 | D12: 78.41.46.2 | E12: 57 | F12: completed | G12: Not Answered | H12: Not Answered | I12: Not Answered | J12: 427944757 | K12: weblink | L12: Not Answered | M12: Not Answered | N12: Digitaliseringsdirektoratet | O12: Not Answered | P12: Not Answered | Q12: Not Answered | R12: Not Answered | S12: Not Answered | T12: Not Answered | U12: Not Answered | V12: Not Answered | W12: Not Answered | X12: Not Answered | Y12: Aase Mestad | Z12: Not Answered | AA12: Ganske fornøyd | AB12: Not Answered | AC12: 5 - star | AD12: Not Answered | AE12: Ganske fornøyd | AF12: Not Answered | AG12: Svært fornøyd | AH12: Not Answered | AI12: Litt fornøyd | AJ12: Not Answered | AK12: 4 - star | AL12: Not Answered | AM12: Not Answered
A13: 114433976163 | B13: 45210.448 | C13: 45210.449 | D13: 78.41.46.2 | E13: 88 | F13: completed | G13: Not Answered | H13: Not Answered | I13: Not Answered | J13: 427944757 | K13: weblink | L13: Not Answered | M13: Not Answered | N13: Digitaliseringsdirektoratet | O13: Not Answered | P13: Not Answered | Q13: Not Answered | R13: Not Answered | S13: Not Answered | T13: Not Answered | U13: Not Answered | V13: Not Answered | W13: Not Answered | X13: Not Answered | Y13: Bjørn Aron Josefsen | Z13: Not Answered | AA13: Litt fornøyd | AB13: Høg kvalitet, men utfordrande samhandling. Kjent og akseptert | AC13: 5 - star | AD13: Not Answered | AE13: Litt fornøyd | AF13: Not Answered | AG13: Litt fornøyd | AH13: Not Answered | AI13: Litt fornøyd | AJ13: Not Answered | AK13: 2 - star | AL13: Not Answered | AM13: Not Answered
... A26: 114456037685 | B26: 45236.643 | C26: 45236.645 | D26: 188.240.90.2 | E26: 108 | F26: completed | G26: Not Answered | H26: Not Answered | I26: Not Answered | J26: 427944757 | K26: weblink | L26: Not Answered | M26: Not Answered | N26: Tolletaten | O26: Not Answered | P26: Not Answered | Q26: Petter Kristiansen | R26: Not Answered | S26: Not Answered | T26: Not Answered | U26: Not Answered | V26: Not Answered | W26: Not Answered | X26: Not Answered | Y26: Not Answered | Z26: Not Answered | AA26: Svært fornøyd | AB26: Not Answered | AC26: I stor grad | AD26: Not Answered | AE26: Svært fornøyd | AF26: Flink til å inkludere og involvere, samt dele av kompetanse | AG26: Svært fornøyd | AH26: Not Answered | AI26: Not Answered | AJ26: Ikke hatt noen dialog utover konsulentene vi har innleid. Så N/A | AK26: I stor grad | AL26: Not Answered | AM26: Not Answered

Sheet mapping
A1: tekst | B1: verdi
A2: Svært misfornøyd | B2: 1
A3: Ganske misfornøyd | B3: 2
A4: Litt misfornøyd | B4: 3
A5: Litt fornøyd | B5: 4
A6: Ganske fornøyd | B6: 5
A7: Svært fornøyd | B7: 6
A8: I liten grad | B8: 1
A9: 2 - star | B9: 2
A10: 3 - star | B10: 3
A11: 4 - star | B11: 4
A12: 5 - star | B12: 5
A13: I stor grad | B13: 6
A14: Not Answered
A15: Ganske fornøyd | B15: 5

Sheet konsulenter
A1: Hans-Petter Vadseth | B1: hp@jpro.no | D1: Manuelt lagt til
A2: Georg Lundesgaard | B2: georg@jpro.no
A5: =IFERROR(__xludf.DUMMYFUNCTION("QUERY(IMPORTRANGE(""https://docs.google.com/spreadsheets/d/1a0Vn8VuzQrdl0jyTLCpfh1956x3u7fUgYxhNH26Dhrk/edit#gid=0"",""Alle!A2:G""), ""select Col1,Col2 where Col1 is not null and Col6 is not null and Col2 is not null order by Col1 "", false)"),"#REF!") -> #REF!

Sheet transform - 2024
A1: =IFERROR(__xludf.DUMMYFUNCTION("query('Kundetilfredshetsundersøkelse -'!A:AS,""select * where Col6 = 'completed'"",true)"),"Response ID") -> Response ID | B1: =IFERROR(__xludf.DUMMYFUNCTION("""COMPUTED_VALUE"""),"Date Created") -> Date Created | C1: =IFERROR(__xludf.DUMMYFUNCTION("""COMPUTED_VALUE"""),"Date Modified") -> Date Modified | D1: =IFERROR(__xludf.DUMMYFUNCTION("""COMPUTED_VALUE"""),"IP Address") -> IP Address | E1: =IFERROR(__xludf.DUMMYFUNCTION("""COMPUTED_VALUE"""),"Duration (sec)") -> Duration (sec) | F1: =IFERROR(__xludf.DUMMYFUNCTION("""COMPUTED_VALUE"""),"Response Status") -> Response Status | G1: =IFERROR(__xludf.DUMMYFUNCTION("""COMPUTED_VALUE"""),"Email") -> Email | H1: =IFERROR(__xludf.DUMMYFUNCTION("""COMPUTED_VALUE"""),"First Name") -> First Name | I1: =IFERROR(__xludf.DUMMYFUNCTION("""COMPUTED_VALUE"""),"Last Name") -> Last Name | J1: =IFERROR(__xludf.DUMMYFUNCTION("""COMPUTED_VALUE"""),"Collector ID") -> Collector ID | K1: =IFERROR(__xludf.DUMMYFUNCTION("""COMPUTED_VALUE"""),"Collector Type") -> Collector Type | L1: =IFERROR(__xludf.DUMMYFUNCTION("""COMPUTED_VALUE"""),"Custom Value") -> Custom Value | M1: =IFERROR(__xludf.DUMMYFUNCTION("""COMPUTED_VALUE"""),"Velg selskap/kunde") -> Velg selskap/kunde | N1: =IFERROR(__xludf.DUMMYFUNCTION("""COMPUTED_VALUE"""),"Tilbakemeldingen gjelder") -> Tilbakemeldingen gjelder | O1: =IFERROR(__xludf.DUMMYFUNCTION("""COMPUTED_VALUE"""),"Tilbakemeldingen gjelder") -> Tilbakemeldingen gjelder | P1: =IFERROR(__xludf.DUMMYFUNCTION("""COMPUTED_VALUE"""),"Tilbakemeldingen gjelder") -> Tilbakemeldingen gjelder | Q1: =IFERROR(__xludf.DUMMYFUNCTION("""COMPUTED_VALUE"""),"Tilbakemeldingen gjelder") -> Tilbakemeldingen gjelder | R1: =IFERROR(__xludf.DUMMYFUNCTION("""COMPUTED_VALUE"""),"Tilbakemeldingen gjelder") -> Tilbakemeldingen gjelder | S1: =IFERROR(__xludf.DUMMYFUNCTION("""COMPUTED_VALUE"""),"Tilbakemeldingen gjelder") -> Tilbakemeldingen gjelder | T1: =IFERROR(__xludf.DUMMYFUNCTION("""COMPUTED_VALUE"""),"Tilbakemeldingen gjelder") -> Tilbakemeldingen gjelder | U1: =IFERROR(__xludf.DUMMYFUNCTION("""COMPUTED_VALUE"""),"Tilbakemeldingen gjelder") -> Tilbakemeldingen gjelder | ... AF1: =IFERROR(__xludf.DUMMYFUNCTION("""COMPUTED_VALUE"""),"Tilbakemeldingen gjelder") -> Tilbakemeldingen gjelder | AG1: =IFERROR(__xludf.DUMMYFUNCTION("""COMPUTED_VALUE"""),"Hvor godt fornøyd er du med det utførte arbeidet til konsulenten fra JProfessionals AS") -> Hvor godt fornøyd er du med det utførte arbeidet til konsulenten fra JProfessionals AS | AH1: =IFERROR(__xludf.DUMMYFUNCTION("""COMPUTED_VALUE"""),"Hvor godt fornøyd er du med det utførte arbeidet til konsulenten fra JProfessionals AS | Kommentar") -> Hvor godt fornøyd er du med det utførte arbeidet til konsulenten fra JProfessionals AS | Kommentar | AI1: =IFERROR(__xludf.DUMMYFUNCTION("""COMPUTED_VALUE"""),"Har konsulenten fra JProfessionals AS den nødvendige kompetansen for arbeidet dere trenger utført?") -> Har konsulenten fra JProfessionals AS den nødvendige kompetansen for arbeidet dere trenger utført? | AJ1: =IFERROR(__xludf.DUMMYFUNCTION("""COMPUTED_VALUE"""),"Har konsulenten fra JProfessionals AS den nødvendige kompetansen for arbeidet dere trenger utført? | Kommentar / Er det kompetanse du savner?") -> Har konsulenten fra JProfessionals AS den nødvendige kompetansen for arbeidet dere trenger utført? | Kommentar / Er det kompetanse du savner? | AK1: =IFERROR(__xludf.DUMMYFUNCTION("""COMPUTED_VALUE"""),"Hvor godt fornøyd er du med konsulenten fra JProfessionals AS sitt bidrag til kompetansedeling innad i ditt team/din organisasjon?") -> Hvor godt fornøyd er du med konsulenten fra JProfessionals AS sitt bidrag til kompetansedeling innad i ditt team/din organisasjon? | AL1: =IFERROR(__xludf.DUMMYFUNCTION("""COMPUTED_VALUE"""),"Hvor godt fornøyd er du med konsulenten fra JProfessionals AS sitt bidrag til kompetansedeling innad i ditt team/din organisasjon? | Kommentar") -> Hvor godt fornøyd er du med konsulenten fra JProfessionals AS sitt bidrag til kompetansedeling innad i ditt team/din organisasjon? | Kommentar | AM1: =IFERROR(__xludf.DUMMYFUNCTION("""COMPUTED_VALUE"""),"Hvor godt fornøyd er du med det generelle samarbeidet og kommunikasjonen med konsulenten fra JProfessionals AS?") -> Hvor godt fornøyd er du med det generelle samarbeidet og kommunikasjonen med konsulenten fra JProfessionals AS? | AN1: =IFERROR(__xludf.DUMMYFUNCTION("""COMPUTED_VALUE"""),"Hvor godt fornøyd er du med det generelle samarbeidet og kommunikasjonen med konsulenten fra JProfessionals AS? | Kommentar") -> Hvor godt fornøyd er du med det generelle samarbeidet og kommunikasjonen med konsulenten fra JProfessionals AS? | Kommentar | AO1: =IFERROR(__xludf.DUMMYFUNCTION("""COMPUTED_VALUE"""),"Hvor godt fornøyd er du med oppfølgingen fra, og samarbeidet med, JProfessionals AS? (valgfritt) - Om JProfessionals ikke er leverandøren du forholder deg til kan du se bort fra dette spørsmålet.") -> Hvor godt fornøyd er du med oppfølgingen fra, og samarbeidet med, JProfessionals AS? (valgfritt) - Om JProfessionals ikke er leverandøren du forholder deg til kan du se bort fra dette spørsmålet. | AP1: =IFERROR(__xludf.DUMMYFUNCTION("""COMPUTED_VALUE"""),"Hvor godt fornøyd er du med oppfølgingen fra, og samarbeidet med, JProfessionals AS? (valgfritt) - Om JProfessionals ikke er leverandøren du forholder deg til kan du se bort fra dette spørsmålet. | Kommentar") -> Hvor godt fornøyd er du med oppfølgingen fra, og samarbeidet med, JProfessionals AS? (valgfritt) - Om JProfessionals ikke er leverandøren du forholder deg til kan du se bort fra dette spørsmålet. | Kommentar | AQ1: =IFERROR(__xludf.DUMMYFUNCTION("""COMPUTED_VALUE"""),"I hvor stor grad synes du at kostnaden for konsulenten fra JProfessionals AS er verdt nytten de tilfører din organisasjon?") -> I hvor stor grad synes du at kostnaden for konsulenten fra JProfessionals AS er verdt nytten de tilfører din organisasjon? | AR1: =IFERROR(__xludf.DUMMYFUNCTION("""COMPUTED_VALUE"""),"I hvor stor grad synes du at kostnaden for konsulenten fra JProfessionals AS er verdt nytten de tilfører din organisasjon? | Kommentar") -> I hvor stor grad synes du at kostnaden for konsulenten fra JProfessionals AS er verdt nytten de tilfører din organisasjon? | Kommentar | AS1: =IFERROR(__xludf.DUMMYFUNCTION("""COMPUTED_VALUE"""),"Er det ytterligere områder eller tjenester du ser behov for bistand til?") -> Er det ytterligere områder eller tjenester du ser behov for bistand til? | AT1: Dato | AU1: Kunde | AV1: Konsulent | AW1: epost | AX1: =AG1 -> Hvor godt fornøyd er du med det utførte arbeidet til konsulenten fra JProfessionals AS | AY1: =AH1 -> Hvor godt fornøyd er du med det utførte arbeidet til konsulenten fra JProfessionals AS | Kommentar | AZ1: =AI1 -> Har konsulenten fra JProfessionals AS den nødvendige kompetansen for arbeidet dere trenger utført? | BA1: =AJ1 -> Har konsulenten fra JProfessionals AS den nødvendige kompetansen for arbeidet dere trenger utført? | Kommentar / Er det kompetanse du savner? | BB1: =AK1 -> Hvor godt fornøyd er du med konsulenten fra JProfessionals AS sitt bidrag til kompetansedeling innad i ditt team/din organisasjon? | BC1: =AL1 -> Hvor godt fornøyd er du med konsulenten fra JProfessionals AS sitt bidrag til kompetansedeling innad i ditt team/din organisasjon? | Kommentar | BD1: =AM1 -> Hvor godt fornøyd er du med det generelle samarbeidet og kommunikasjonen med konsulenten fra JProfessionals AS? | BE1: =AN1 -> Hvor godt fornøyd er du med det generelle samarbeidet og kommunikasjonen med konsulenten fra JProfessionals AS? | Kommentar | ... BJ1: =AS1 -> Er det ytterligere områder eller tjenester du ser behov for bistand til?
A2: =IFERROR(__xludf.DUMMYFUNCTION("""COMPUTED_VALUE"""),1.14735374663E11) -> 114735374663 | B2: =IFERROR(__xludf.DUMMYFUNCTION("""COMPUTED_VALUE"""),45609.534421296295) -> 45609.534 | C2: =IFERROR(__xludf.DUMMYFUNCTION("""COMPUTED_VALUE"""),45609.53721064815) -> 45609.537 | D2: =IFERROR(__xludf.DUMMYFUNCTION("""COMPUTED_VALUE"""),"62.92.224.122") -> 62.92.224.122 | E2: =IFERROR(__xludf.DUMMYFUNCTION("""COMPUTED_VALUE"""),240.0) -> 240 | F2: =IFERROR(__xludf.DUMMYFUNCTION("""COMPUTED_VALUE"""),"completed") -> completed | G2: =IFERROR(__xludf.DUMMYFUNCTION("""COMPUTED_VALUE"""),"Not Answered") -> Not Answered | H2: =IFERROR(__xludf.DUMMYFUNCTION("""COMPUTED_VALUE"""),"Not Answered") -> Not Answered | I2: =IFERROR(__xludf.DUMMYFUNCTION("""COMPUTED_VALUE"""),"Not Answered") -> Not Answered | J2: =IFERROR(__xludf.DUMMYFUNCTION("""COMPUTED_VALUE"""),4.33598082E8) -> 433598082 | K2: =IFERROR(__xludf.DUMMYFUNCTION("""COMPUTED_VALUE"""),"weblink") -> weblink | L2: =IFERROR(__xludf.DUMMYFUNCTION("""COMPUTED_VALUE"""),"Not Answered") -> Not Answered | M2: =IFERROR(__xludf.DUMMYFUNCTION("""COMPUTED_VALUE"""),"Husbanken") -> Husbanken | N2: =IFERROR(__xludf.DUMMYFUNCTION("""COMPUTED_VALUE"""),"Not Answered") -> Not Answered | O2: =IFERROR(__xludf.DUMMYFUNCTION("""COMPUTED_VALUE"""),"Not Answered") -> Not Answered | P2: =IFERROR(__xludf.DUMMYFUNCTION("""COMPUTED_VALUE"""),"Not Answered") -> Not Answered | Q2: =IFERROR(__xludf.DUMMYFUNCTION("""COMPUTED_VALUE"""),"Not Answered") -> Not Answered | R2: =IFERROR(__xludf.DUMMYFUNCTION("""COMPUTED_VALUE"""),"Not Answered") -> Not Answered | S2: =IFERROR(__xludf.DUMMYFUNCTION("""COMPUTED_VALUE"""),"Not Answered") -> Not Answered | T2: =IFERROR(__xludf.DUMMYFUNCTION("""COMPUTED_VALUE"""),"Not Answered") -> Not Answered | U2: =IFERROR(__xludf.DUMMYFUNCTION("""COMPUTED_VALUE"""),"Not Answered") -> Not Answered | V2: =IFERROR(__xludf.DUMMYFUNCTION("""COMPUTED_VALUE"""),"Not Answered") -> Not Answered | W2: =IFERROR(__xludf.DUMMYFUNCTION("""COMPUTED_VALUE"""),"Terje Wallem") -> Terje Wallem | X2: =IFERROR(__xludf.DUMMYFUNCTION("""COMPUTED_VALUE"""),"Not Answered") -> Not Answered | Y2: =IFERROR(__xludf.DUMMYFUNCTION("""COMPUTED_VALUE"""),"Not Answered") -> Not Answered | Z2: =IFERROR(__xludf.DUMMYFUNCTION("""COMPUTED_VALUE"""),"Not Answered") -> Not Answered | AA2: =IFERROR(__xludf.DUMMYFUNCTION("""COMPUTED_VALUE"""),"Not Answered") -> Not Answered | AB2: =IFERROR(__xludf.DUMMYFUNCTION("""COMPUTED_VALUE"""),"Not Answered") -> Not Answered | AC2: =IFERROR(__xludf.DUMMYFUNCTION("""COMPUTED_VALUE"""),"Not Answered") -> Not Answered | AD2: =IFERROR(__xludf.DUMMYFUNCTION("""COMPUTED_VALUE"""),"Not Answered") -> Not Answered | AE2: =IFERROR(__xludf.DUMMYFUNCTION("""COMPUTED_VALUE"""),"Not Answered") -> Not Answered | AF2: =IFERROR(__xludf.DUMMYFUNCTION("""COMPUTED_VALUE"""),"Not Answered") -> Not Answered | AG2: =IFERROR(__xludf.DUMMYFUNCTION("""COMPUTED_VALUE"""),"Svært fornøyd") -> Svært fornøyd | AH2: =IFERROR(__xludf.DUMMYFUNCTION("""COMPUTED_VALUE"""),"Not Answered") -> Not Answered | AI2: =IFERROR(__xludf.DUMMYFUNCTION("""COMPUTED_VALUE"""),"I stor grad") -> I stor grad | AJ2: =IFERROR(__xludf.DUMMYFUNCTION("""COMPUTED_VALUE"""),"Not Answered") -> Not Answered | AK2: =IFERROR(__xludf.DUMMYFUNCTION("""COMPUTED_VALUE"""),"Svært fornøyd") -> Svært fornøyd | AL2: =IFERROR(__xludf.DUMMYFUNCTION("""COMPUTED_VALUE"""),"Not Answered") -> Not Answered | AM2: =IFERROR(__xludf.DUMMYFUNCTION("""COMPUTED_VALUE"""),"Svært fornøyd") -> Svært fornøyd | AN2: =IFERROR(__xludf.DUMMYFUNCTION("""COMPUTED_VALUE"""),"Not Answered") -> Not Answered | AO2: =IFERROR(__xludf.DUMMYFUNCTION("""COMPUTED_VALUE"""),"Svært fornøyd") -> Svært fornøyd | AP2: =IFERROR(__xludf.DUMMYFUNCTION("""COMPUTED_VALUE"""),"(Overhuset) Ikke vært så mye dialog, men mangler ikke noe :-)") -> (Overhuset) Ikke vært så mye dialog, men mangler ikke noe :-) | AQ2: =IFERROR(__xludf.DUMMYFUNCTION("""COMPUTED_VALUE"""),"5 - star") -> 5 - star | AR2: =IFERROR(__xludf.DUMMYFUNCTION("""COMPUTED_VALUE"""),"Not Answered") -> Not Answered | AS2: =IFERROR(__xludf.DUMMYFUNCTION("""COMPUTED_VALUE"""),"Not Answered") -> Not Answered | AT2: =if(ISNUMBER(A2),B2,) -> 45609.534 | AU2: =if(ISNUMBER(A2),M2,) -> Husbanken | AV2: =IFERROR(__xludf.DUMMYFUNCTION("if(ISNUMBER(A2),FILTER(N2:AF2,REGEXMATCH(N2:AF2, ""Not Answered"")=FALSE),)"),"Terje Wallem") -> Terje Wallem | AW2: =if(ISNUMBER($C2), VLOOKUP(AV2, konsulenter!$A$1:$B99,2,false),) -> #N/A | AX2: =if(ISNUMBER($C2), VLOOKUP(AG2, mapping!$A$2:$B99,2,false),) -> 6 | AY2: =if(ISNUMBER($C2), IF(AH2="Not Answered","-",AH2),) -> - | AZ2: =if(ISNUMBER($C2), VLOOKUP(AI2, mapping!$A$2:$B99,2,false),) -> 6 | BA2: =if(ISNUMBER($C2), IF(AJ2="Not Answered","-",AJ2),) -> - | BB2: =if(ISNUMBER($C2), VLOOKUP(AK2, mapping!$A$2:$B99,2,false),) -> 6 | BC2: =if(ISNUMBER($C2), IF(AL2="Not Answered","-",AL2),) -> - | BD2: =if(ISNUMBER($C2), VLOOKUP(AM2, mapping!$A$2:$B99,2,false),) -> 6 | BE2: =if(ISNUMBER($C2), IF(AN2="Not Answered","-",AN2),) -> - | BF2: =if(ISNUMBER($C2), VLOOKUP(AO2, mapping!$A$2:$B99,2,false),) -> 6 | BG2: =if(ISNUMBER($C2), IF(AP2="Not Answered","-",AP2),) -> (Overhuset) Ikke vært så mye dialog, men mangler ikke noe :-) | BH2: =if(ISNUMBER($C2), VLOOKUP(AQ2, mapping!$A$2:$B99,2,false),) -> 5 | BI2: =if(ISNUMBER($C2), IF(AR2="Not Answered","-",AR2),) -> - | BJ2: =if(ISNUMBER($C2), IF(AS2="Not Answered","-",AS2),) -> -
A3: =IFERROR(__xludf.DUMMYFUNCTION("""COMPUTED_VALUE"""),1.14714414449E11) -> 114714414449 | B3: =IFERROR(__xludf.DUMMYFUNCTION("""COMPUTED_VALUE"""),45582.54043981481) -> 45582.54 | C3: =IFERROR(__xludf.DUMMYFUNCTION("""COMPUTED_VALUE"""),45582.541354166664) -> 45582.541 | D3: =IFERROR(__xludf.DUMMYFUNCTION("""COMPUTED_VALUE"""),"81.175.27.28") -> 81.175.27.28 | E3: =IFERROR(__xludf.DUMMYFUNCTION("""COMPUTED_VALUE"""),79.0) -> 79 | F3: =IFERROR(__xludf.DUMMYFUNCTION("""COMPUTED_VALUE"""),"completed") -> completed | G3: =IFERROR(__xludf.DUMMYFUNCTION("""COMPUTED_VALUE"""),"Not Answered") -> Not Answered | H3: =IFERROR(__xludf.DUMMYFUNCTION("""COMPUTED_VALUE"""),"Not Answered") -> Not Answered | I3: =IFERROR(__xludf.DUMMYFUNCTION("""COMPUTED_VALUE"""),"Not Answered") -> Not Answered | J3: =IFERROR(__xludf.DUMMYFUNCTION("""COMPUTED_VALUE"""),4.33188881E8) -> 433188881 | K3: =IFERROR(__xludf.DUMMYFUNCTION("""COMPUTED_VALUE"""),"weblink") -> weblink | L3: =IFERROR(__xludf.DUMMYFUNCTION("""COMPUTED_VALUE"""),"Not Answered") -> Not Answered | M3: =IFERROR(__xludf.DUMMYFUNCTION("""COMPUTED_VALUE"""),"SPK") -> SPK | N3: =IFERROR(__xludf.DUMMYFUNCTION("""COMPUTED_VALUE"""),"Not Answered") -> Not Answered | O3: =IFERROR(__xludf.DUMMYFUNCTION("""COMPUTED_VALUE"""),"Not Answered") -> Not Answered | P3: =IFERROR(__xludf.DUMMYFUNCTION("""COMPUTED_VALUE"""),"Not Answered") -> Not Answered | Q3: =IFERROR(__xludf.DUMMYFUNCTION("""COMPUTED_VALUE"""),"Not Answered") -> Not Answered | R3: =IFERROR(__xludf.DUMMYFUNCTION("""COMPUTED_VALUE"""),"Not Answered") -> Not Answered | S3: =IFERROR(__xludf.DUMMYFUNCTION("""COMPUTED_VALUE"""),"Not Answered") -> Not Answered | T3: =IFERROR(__xludf.DUMMYFUNCTION("""COMPUTED_VALUE"""),"Not Answered") -> Not Answered | U3: =IFERROR(__xludf.DUMMYFUNCTION("""COMPUTED_VALUE"""),"Not Answered") -> Not Answered | ... AE3: =IFERROR(__xludf.DUMMYFUNCTION("""COMPUTED_VALUE"""),"Not Answered") -> Not Answered | AF3: =IFERROR(__xludf.DUMMYFUNCTION("""COMPUTED_VALUE"""),"Ingebrigt Berg") -> Ingebrigt Berg | AG3: =IFERROR(__xludf.DUMMYFUNCTION("""COMPUTED_VALUE"""),"Svært fornøyd") -> Svært fornøyd | AH3: =IFERROR(__xludf.DUMMYFUNCTION("""COMPUTED_VALUE"""),"Kunnskapsrik, omgjengelig, tar initiativ. ") -> Kunnskapsrik, omgjengelig, tar initiativ. | AI3: =IFERROR(__xludf.DUMMYFUNCTION("""COMPUTED_VALUE"""),"I stor grad") -> I stor grad | AJ3: =IFERROR(__xludf.DUMMYFUNCTION("""COMPUTED_VALUE"""),"Not Answered") -> Not Answered | AK3: =IFERROR(__xludf.DUMMYFUNCTION("""COMPUTED_VALUE"""),"Svært fornøyd") -> Svært fornøyd | AL3: =IFERROR(__xludf.DUMMYFUNCTION("""COMPUTED_VALUE"""),"Not Answered") -> Not Answered | AM3: =IFERROR(__xludf.DUMMYFUNCTION("""COMPUTED_VALUE"""),"Svært fornøyd") -> Svært fornøyd | AN3: =IFERROR(__xludf.DUMMYFUNCTION("""COMPUTED_VALUE"""),"Not Answered") -> Not Answered | AO3: =IFERROR(__xludf.DUMMYFUNCTION("""COMPUTED_VALUE"""),"Not Answered") -> Not Answered | AP3: =IFERROR(__xludf.DUMMYFUNCTION("""COMPUTED_VALUE"""),"Not Answered") -> Not Answered | AQ3: =IFERROR(__xludf.DUMMYFUNCTION("""COMPUTED_VALUE"""),"I stor grad") -> I stor grad | AR3: =IFERROR(__xludf.DUMMYFUNCTION("""COMPUTED_VALUE"""),"Not Answered") -> Not Answered | AS3: =IFERROR(__xludf.DUMMYFUNCTION("""COMPUTED_VALUE"""),"Not Answered") -> Not Answered | AT3: =if(ISNUMBER(A3),B3,) -> 45582.54 | AU3: =if(ISNUMBER(A3),M3,) -> SPK | AV3: =IFERROR(__xludf.DUMMYFUNCTION("if(ISNUMBER(A3),FILTER(N3:AF3,REGEXMATCH(N3:AF3, ""Not Answered"")=FALSE),)"),"Ingebrigt Berg") -> Ingebrigt Berg | AW3: =if(ISNUMBER($C3), VLOOKUP(AV3, konsulenter!$A$1:$B99,2,false),) -> #N/A | AX3: =if(ISNUMBER($C3), VLOOKUP(AG3, mapping!$A$2:$B99,2,false),) -> 6 | AY3: =if(ISNUMBER($C3), IF(AH3="Not Answered","-",AH3),) -> Kunnskapsrik, omgjengelig, tar initiativ. | AZ3: =if(ISNUMBER($C3), VLOOKUP(AI3, mapping!$A$2:$B99,2,false),) -> 6 | BA3: =if(ISNUMBER($C3), IF(AJ3="Not Answered","-",AJ3),) -> - | BB3: =if(ISNUMBER($C3), VLOOKUP(AK3, mapping!$A$2:$B99,2,false),) -> 6 | BC3: =if(ISNUMBER($C3), IF(AL3="Not Answered","-",AL3),) -> - | BD3: =if(ISNUMBER($C3), VLOOKUP(AM3, mapping!$A$2:$B99,2,false),) -> 6 | BE3: =if(ISNUMBER($C3), IF(AN3="Not Answered","-",AN3),) -> - | BF3: =if(ISNUMBER($C3), VLOOKUP(AO3, mapping!$A$2:$B99,2,false),) | BG3: =if(ISNUMBER($C3), IF(AP3="Not Answered","-",AP3),) -> - | BH3: =if(ISNUMBER($C3), VLOOKUP(AQ3, mapping!$A$2:$B99,2,false),) -> 6 | BI3: =if(ISNUMBER($C3), IF(AR3="Not Answered","-",AR3),) -> - | BJ3: =if(ISNUMBER($C3), IF(AS3="Not Answered","-",AS3),) -> -
A4: =IFERROR(__xludf.DUMMYFUNCTION("""COMPUTED_VALUE"""),1.14714413253E11) -> 114714413253 | B4: =IFERROR(__xludf.DUMMYFUNCTION("""COMPUTED_VALUE"""),45582.515694444446) -> 45582.516 | C4: =IFERROR(__xludf.DUMMYFUNCTION("""COMPUTED_VALUE"""),45582.563159722224) -> 45582.563 | D4: =IFERROR(__xludf.DUMMYFUNCTION("""COMPUTED_VALUE"""),"46.212.44.252") -> 46.212.44.252 | E4: =IFERROR(__xludf.DUMMYFUNCTION("""COMPUTED_VALUE"""),4100.0) -> 4100 | F4: =IFERROR(__xludf.DUMMYFUNCTION("""COMPUTED_VALUE"""),"completed") -> completed | G4: =IFERROR(__xludf.DUMMYFUNCTION("""COMPUTED_VALUE"""),"Not Answered") -> Not Answered | H4: =IFERROR(__xludf.DUMMYFUNCTION("""COMPUTED_VALUE"""),"Not Answered") -> Not Answered | I4: =IFERROR(__xludf.DUMMYFUNCTION("""COMPUTED_VALUE"""),"Not Answered") -> Not Answered | J4: =IFERROR(__xludf.DUMMYFUNCTION("""COMPUTED_VALUE"""),4.33188881E8) -> 433188881 | K4: =IFERROR(__xludf.DUMMYFUNCTION("""COMPUTED_VALUE"""),"weblink") -> weblink | L4: =IFERROR(__xludf.DUMMYFUNCTION("""COMPUTED_VALUE"""),"Not Answered") -> Not Answered | M4: =IFERROR(__xludf.DUMMYFUNCTION("""COMPUTED_VALUE"""),"Entur") -> Entur | N4: =IFERROR(__xludf.DUMMYFUNCTION("""COMPUTED_VALUE"""),"Not Answered") -> Not Answered | O4: =IFERROR(__xludf.DUMMYFUNCTION("""COMPUTED_VALUE"""),"Not Answered") -> Not Answered | P4: =IFERROR(__xludf.DUMMYFUNCTION("""COMPUTED_VALUE"""),"Not Answered") -> Not Answered | Q4: =IFERROR(__xludf.DUMMYFUNCTION("""COMPUTED_VALUE"""),"Not Answered") -> Not Answered | R4: =IFERROR(__xludf.DUMMYFUNCTION("""COMPUTED_VALUE"""),"Not Answered") -> Not Answered | S4: =IFERROR(__xludf.DUMMYFUNCTION("""COMPUTED_VALUE"""),"Not Answered") -> Not Answered | T4: =IFERROR(__xludf.DUMMYFUNCTION("""COMPUTED_VALUE"""),"Not Answered") -> Not Answered | U4: =IFERROR(__xludf.DUMMYFUNCTION("""COMPUTED_VALUE"""),"Not Answered") -> Not Answered | ... Z4: =IFERROR(__xludf.DUMMYFUNCTION("""COMPUTED_VALUE"""),"Not Answered") -> Not Answered | AA4: =IFERROR(__xludf.DUMMYFUNCTION("""COMPUTED_VALUE"""),"Bent Lorentzen") -> Bent Lorentzen | AB4: =IFERROR(__xludf.DUMMYFUNCTION("""COMPUTED_VALUE"""),"Not Answered") -> Not Answered | AC4: =IFERROR(__xludf.DUMMYFUNCTION("""COMPUTED_VALUE"""),"Not Answered") -> Not Answered | AD4: =IFERROR(__xludf.DUMMYFUNCTION("""COMPUTED_VALUE"""),"Not Answered") -> Not Answered | AE4: =IFERROR(__xludf.DUMMYFUNCTION("""COMPUTED_VALUE"""),"Not Answered") -> Not Answered | AF4: =IFERROR(__xludf.DUMMYFUNCTION("""COMPUTED_VALUE"""),"Not Answered") -> Not Answered | AG4: =IFERROR(__xludf.DUMMYFUNCTION("""COMPUTED_VALUE"""),"Svært fornøyd") -> Svært fornøyd | AH4: =IFERROR(__xludf.DUMMYFUNCTION("""COMPUTED_VALUE"""),"Bent er en svært kompetent teknolog som leverer arbeid av høy kvalitet. Hans erfaring og kompetanse innenfor feltet har bidratt til gode diskusjoner i teamet, gode løsninger, kunnskapsdeling og har vært med på å dra teamet i en veldig god retning. ") -> Bent er en svært kompetent teknolog som leverer arbeid av høy kvalitet. Hans erfaring og kompetanse innenfor feltet har bidratt til gode diskusjoner i teamet, gode løsninger, kunnskapsdeling og har vært med på å dra teamet i en veldig god retning. | AI4: =IFERROR(__xludf.DUMMYFUNCTION("""COMPUTED_VALUE"""),"I stor grad") -> I stor grad | AJ4: =IFERROR(__xludf.DUMMYFUNCTION("""COMPUTED_VALUE"""),"Bent har absolutt den nødvendige kompetansen for det arbeidet Entur trenger utført, og av de få områdene han ikke hadde kunnskap til fra før har han vist stor lærevilje og raskt kommet opp på et høyt kunnskapsnivå for ny teknologi og ikke minst domene.") -> Bent har absolutt den nødvendige kompetansen for det arbeidet Entur trenger utført, og av de få områdene han ikke hadde kunnskap til fra før har han vist stor lærevilje og raskt kommet opp på et høyt kunnskapsnivå for ny teknologi og ikke minst domene. | AK4: =IFERROR(__xludf.DUMMYFUNCTION("""COMPUTED_VALUE"""),"Svært fornøyd") -> Svært fornøyd | AL4: =IFERROR(__xludf.DUMMYFUNCTION("""COMPUTED_VALUE"""),"Som nevnt som kommentar i det første spørsmålet bidrar Bent i aller største grad til kompetansedeling innad i teamet. Hans evne til å vise forståelse og tålmodighet for de som skal tilegne seg ny kunnskap gjør han til en god mentor.") -> Som nevnt som kommentar i det første spørsmålet bidrar Bent i aller største grad til kompetansedeling innad i teamet. Hans evne til å vise forståelse og tålmodighet for de som skal tilegne seg ny kunnskap gjør han til en god mentor. | AM4: =IFERROR(__xludf.DUMMYFUNCTION("""COMPUTED_VALUE"""),"Svært fornøyd") -> Svært fornøyd | AN4: =IFERROR(__xludf.DUMMYFUNCTION("""COMPUTED_VALUE"""),"Bent er veldig samarbeidsvillig og stiller alltid opp på kort varsel hvis noen trenger hjelp eller ønsker å arbeide sammen med ham. Bent og jeg (produktleder) har ukentlige møter for å planlegge uken jeg synes er veldig verdifullt. Han deltar alltid flitt"&"ig i møter, har tydelige meninger, men er også alltid åpen for andres meninger og er villig til å diskutere emner med teamet før en endelig beslutning tas.") -> Bent er veldig samarbeidsvillig og stiller alltid opp på kort varsel hvis noen trenger hjelp eller ønsker å arbeide sammen med ham. Bent og jeg (produktleder) har ukentlige møter for å planlegge uken jeg synes er veldig verdifullt. Han deltar alltid flittig i møter, har tydelige meninger, men er også alltid åpen for andres meninger og er villig til å diskutere emner med teamet før en endelig beslutning tas. | AO4: =IFERROR(__xludf.DUMMYFUNCTION("""COMPUTED_VALUE"""),"Not Answered") -> Not Answered | AP4: =IFERROR(__xludf.DUMMYFUNCTION("""COMPUTED_VALUE"""),"Not Answered") -> Not Answered | AQ4: =IFERROR(__xludf.DUMMYFUNCTION("""COMPUTED_VALUE"""),"I stor grad") -> I stor grad | AR4: =IFERROR(__xludf.DUMMYFUNCTION("""COMPUTED_VALUE"""),"Not Answered") -> Not Answered | AS4: =IFERROR(__xludf.DUMMYFUNCTION("""COMPUTED_VALUE"""),"Not Answered") -> Not Answered | AT4: =if(ISNUMBER(A4),B4,) -> 45582.516 | AU4: =if(ISNUMBER(A4),M4,) -> Entur | AV4: =IFERROR(__xludf.DUMMYFUNCTION("if(ISNUMBER(A4),FILTER(N4:AF4,REGEXMATCH(N4:AF4, ""Not Answered"")=FALSE),)"),"Bent Lorentzen") -> Bent Lorentzen | AW4: =if(ISNUMBER($C4), VLOOKUP(AV4, konsulenter!$A$1:$B99,2,false),) -> #N/A | AX4: =if(ISNUMBER($C4), VLOOKUP(AG4, mapping!$A$2:$B99,2,false),) -> 6 | AY4: =if(ISNUMBER($C4), IF(AH4="Not Answered","-",AH4),) -> Bent er en svært kompetent teknolog som leverer arbeid av høy kvalitet. Hans erfaring og kompetanse innenfor feltet har bidratt til gode diskusjoner i teamet, gode løsninger, kunnskapsdeling og har vært med på å dra teamet i en veldig god retning. | AZ4: =if(ISNUMBER($C4), VLOOKUP(AI4, mapping!$A$2:$B99,2,false),) -> 6 | BA4: =if(ISNUMBER($C4), IF(AJ4="Not Answered","-",AJ4),) -> Bent har absolutt den nødvendige kompetansen for det arbeidet Entur trenger utført, og av de få områdene han ikke hadde kunnskap til fra før har han vist stor lærevilje og raskt kommet opp på et høyt kunnskapsnivå for ny teknologi og ikke minst domene. | BB4: =if(ISNUMBER($C4), VLOOKUP(AK4, mapping!$A$2:$B99,2,false),) -> 6 | BC4: =if(ISNUMBER($C4), IF(AL4="Not Answered","-",AL4),) -> Som nevnt som kommentar i det første spørsmålet bidrar Bent i aller største grad til kompetansedeling innad i teamet. Hans evne til å vise forståelse og tålmodighet for de som skal tilegne seg ny kunnskap gjør han til en god mentor. | BD4: =if(ISNUMBER($C4), VLOOKUP(AM4, mapping!$A$2:$B99,2,false),) -> 6 | BE4: =if(ISNUMBER($C4), IF(AN4="Not Answered","-",AN4),) -> Bent er veldig samarbeidsvillig og stiller alltid opp på kort varsel hvis noen trenger hjelp eller ønsker å arbeide sammen med ham. Bent og jeg (produktleder) har ukentlige møter for å planlegge uken jeg synes er veldig verdifullt. Han deltar alltid flittig i møter, har tydelige meninger, men er også alltid åpen for andres meninger og er villig til å diskutere emner med teamet før en endelig beslutning tas. | BF4: =if(ISNUMBER($C4), VLOOKUP(AO4, mapping!$A$2:$B99,2,false),) | BG4: =if(ISNUMBER($C4), IF(AP4="Not Answered","-",AP4),) -> - | BH4: =if(ISNUMBER($C4), VLOOKUP(AQ4, mapping!$A$2:$B99,2,false),) -> 6 | BI4: =if(ISNUMBER($C4), IF(AR4="Not Answered","-",AR4),) -> - | BJ4: =if(ISNUMBER($C4), IF(AS4="Not Answered","-",AS4),) -> -
